<?xml version="1.0" encoding="utf-8"?>
<!-- This URDF was automatically created by SolidWorks to URDF Exporter! Originally created by Stephen Brawner (brawner@gmail.com) 
     Commit Version: 1.6.0-4-g7f85cfe  Build Version: 1.6.7995.38578
     For more information, please see http://wiki.ros.org/sw_urdf_exporter -->
<robot
  name="smacp">
  <link
    name="base_link">
    <inertial>
      <origin
        xyz="-1.9504E-06 0.018767 -0.045855"
        rpy="0 0 0" />
      <mass
        value="0.18623" />
      <inertia
        ixx="0.00023598"
        ixy="1.6952E-09"
        ixz="-1.4231E-09"
        iyy="0.00050787"
        iyz="-1.0088E-05"
        izz="0.00030832" />
    </inertial>
    <visual>
      <origin
        xyz="0 0 0"
        rpy="0 0 0" />
      <geometry>
        <mesh
          filename="package://smacp/meshes/base_link.STL" />
      </geometry>
      <material
        name="">
        <color
          rgba="0.75294 0.75294 0.75294 1" />
      </material>
    </visual>
    <collision>
      <origin
        xyz="0 0 0"
        rpy="0 0 0" />
      <geometry>
        <mesh
          filename="package://smacp/meshes/base_link.STL" />
      </geometry>
    </collision>
  </link>
  <link
    name="Rueda_Izq">
    <inertial>
      <origin
        xyz="1.97548833374347E-05 -5.93702393741503E-05 0.010581849079838"
        rpy="0 0 0" />
      <mass
        value="0.0108737045107905" />
      <inertia
        ixx="1.12084842661512E-06"
        ixy="4.65069079195102E-10"
        ixz="-7.72463451002501E-10"
        iyy="1.12069201644994E-06"
        iyz="-6.5340739355055E-10"
        izz="1.51855757742517E-06" />
    </inertial>
    <visual>
      <origin
        xyz="0 0 0"
        rpy="0 0 0" />
      <geometry>
        <mesh
          filename="package://smacp/meshes/Rueda_Izq.STL" />
      </geometry>
      <material
        name="">
        <color
          rgba="0.792156862745098 0.819607843137255 0.933333333333333 1" />
      </material>
    </visual>
    <collision>
      <origin
        xyz="0 0 0"
        rpy="0 0 0" />
      <geometry>
        <mesh
          filename="package://smacp/meshes/Rueda_Izq.STL" />
      </geometry>
    </collision>
  </link>
  <joint
    name="Motor_Izq"
    type="continuous">
    <origin
      xyz="-0.05177 -9.5E-05 0.007875"
      rpy="1.5708 -0.85 -1.5708" />
    <parent
      link="base_link" />
    <child
      link="Rueda_Izq" />
    <axis
      xyz="0 0 1" />
  </joint>
  <link
    name="Rueda_Der">
    <inertial>
      <origin
        xyz="1.97548833374139E-05 -5.93702393741511E-05 0.0105818490798387"
        rpy="0 0 0" />
      <mass
        value="0.0108737045107905" />
      <inertia
        ixx="1.12084842661512E-06"
        ixy="4.65069079194996E-10"
        ixz="-7.72463451002481E-10"
        iyy="1.12069201644994E-06"
        iyz="-6.53407393550393E-10"
        izz="1.51855757742517E-06" />
    </inertial>
    <visual>
      <origin
        xyz="0 0 0"
        rpy="0 0 0" />
      <geometry>
        <mesh
          filename="package://smacp/meshes/Rueda_Der.STL" />
      </geometry>
      <material
        name="">
        <color
          rgba="0.792156862745098 0.819607843137255 0.933333333333333 1" />
      </material>
    </visual>
    <collision>
      <origin
        xyz="0 0 0"
        rpy="0 0 0" />
      <geometry>
        <mesh
          filename="package://smacp/meshes/Rueda_Der.STL" />
      </geometry>
    </collision>
  </link>
  <joint
    name="Motor_Der"
    type="continuous">
    <origin
      xyz="0.05177 -9.5E-05 0.007875"
      rpy="1.5708 -0.85 1.5708" />
    <parent
      link="base_link" />
    <child
      link="Rueda_Der" />
    <axis
      xyz="0 0 1" />
  </joint>
</robot>